Workbook

Sheet Dashboard
A1: 📦 Elegoo — Filament Reference | v3
A3: CATALOG SUMMARY
A4: Total Catalog Entries (active) | B4: =COUNTA(Catalog!C3:C1000)-COUNTIF(Catalog!T3:T1000,"~[DISCONTINUED~]*") -> 227
A5: Tier S — Premium | B5: =COUNTIF(Catalog!R3:R1000,"S") -> 0
A6: Tier A — Excellent | B6: =COUNTIF(Catalog!R3:R1000,"A") -> 75
A7: Tier B — Good | B7: =COUNTIF(Catalog!R3:R1000,"B") -> 38
A8: Tier C — Specialty | B8: =COUNTIF(Catalog!R3:R1000,"C") -> 114
A9: Require AMS Adapter Ring | B9: =COUNTIF(Catalog!J3:J1000,"Yes") -> 227
A11: TIER LEGEND
A12: S | B12: Premium — first-party or best-in-class; optimized profiles, top AMS reliability
A13: A | B13: Excellent — high quality, tested profiles, reliable AMS performance
A14: B | B14: Good — solid performer with minor caveats (e.g. needs adapter ring, temp adjustment)
A15: C | B15: Specialty — limited AMS use, requires special setup, or niche material
A17: INVENTORY
A18: On-hand spool inventory is tracked separately in Filament_Inventory.xlsx, not in this workbook.
A19: File Generated | B19: =Config!$B$5 -> 2026-10-08
A21: AMS ADAPTER RING STATUS
A22: =IF(COUNTIF(Catalog!J3:J1000,"Yes")>0,"⚠ One or more filaments require the AMS Adapter Ring — see Catalog column J","✓ No filaments in this catalog require the AMS Adapter Ring") -> ⚠ One or more filaments require the AMS Adapter Ring — see Catalog column J
A24: BY MATERIAL TYPE
A25: Material Type | B25: Catalog Entries
A26: ASA | B26: =COUNTIF(Catalog!A3:A700,"ASA") -> 6
A27: ASA-CF | B27: =COUNTIF(Catalog!A3:A700,"ASA-CF") -> 6
A28: PETG (Rapid) | B28: =COUNTIF(Catalog!A3:A700,"PETG (Rapid)") -> 12
A29: PETG Pro | B29: =COUNTIF(Catalog!A3:A700,"PETG Pro") -> 7
A30: PETG Translucent | B30: =COUNTIF(Catalog!A3:A700,"PETG Translucent") -> 11
A31: PETG-CF | B31: =COUNTIF(Catalog!A3:A700,"PETG-CF") -> 5
A32: PLA | B32: =COUNTIF(Catalog!A3:A700,"PLA") -> 18
A33: PLA (RFID) emoji Brand Edition | B33: =COUNTIF(Catalog!A3:A700,"PLA (RFID) emoji Brand Edition") -> 17
A34: PLA Basic | B34: =COUNTIF(Catalog!A3:A700,"PLA Basic") -> 19
A35: PLA CMYK | B35: =COUNTIF(Catalog!A3:A700,"PLA CMYK") -> 4
A36: PLA Galaxy | B36: =COUNTIF(Catalog!A3:A700,"PLA Galaxy") -> 3
A37: PLA Glow | B37: =COUNTIF(Catalog!A3:A700,"PLA Glow") -> 5
A38: PLA Marble | B38: =COUNTIF(Catalog!A3:A700,"PLA Marble") -> 3
A39: PLA Matte | B39: =COUNTIF(Catalog!A3:A700,"PLA Matte") -> 9
A40: PLA Metallic | B40: =COUNTIF(Catalog!A3:A700,"PLA Metallic") -> 4
A41: PLA Plus | B41: =COUNTIF(Catalog!A3:A700,"PLA Plus") -> 17
A42: PLA Pro | B42: =COUNTIF(Catalog!A3:A700,"PLA Pro") -> 14
A43: PLA Silk | B43: =COUNTIF(Catalog!A3:A700,"PLA Silk") -> 16
A44: PLA Sparkle | B44: =COUNTIF(Catalog!A3:A700,"PLA Sparkle") -> 7
A45: PLA Wood | B45: =COUNTIF(Catalog!A3:A700,"PLA Wood") -> 4
...

Sheet Catalog
A1: Elegoo — Filament Catalog
A2: Material Type | B2: SKU / Part No. | C2: Product Name | D2: Color Name | E2: Color Swatch | F2: Hex Code | G2: Diameter | H2: Diameter Tolerance | I2: Spool Type | J2: AMS Adapter Required | K2: Print Temp Range | L2: Bed Temp Range | M2: Drying Temp / Time | N2: AMS X/P | O2: AMS Lite | P2: AMS 2 Pro | Q2: AMS HT | R2: Tier | S2: Tier Rationale | T2: Notes
A3: ASA | B3: EL-ASA-GN | C3: Elegoo ASA | D3: ASA Green | F3: #00CC33 | G3: 1.75mm | H3: ±0.03mm | I3: Cardboard | J3: Yes | K3: 240–260°C | L3: 75–95°C | M3: 70°C / 8h | N3: ⚠ | O3: ✗ | P3: ⚠ | Q3: ⚠ | R3: A | S3: Color and official 6-color line count confirmed (us.elegoo.com official product page — this catalog originally assumed a 12-color line; corrected to the real 6-color line this pass: Deep Black, White, Blue, ASA Green, Grey, Red); hex via 3dfilamentprofiles.com | T3: Cardboard spool — AMS Adapter Ring required for all AMS variants; enclosure recommended (ASA); AMS Lite ✗ (open-frame, no ASA support) | Hex: manufacturer-listed value (3dfilamentprofiles.com)
A4: ASA | B4: EL-ASA-BL | C4: Elegoo ASA | D4: Blue | F4: #0C2388 | G4: 1.75mm | H4: ±0.03mm | I4: Cardboard | J4: Yes | K4: 240–260°C | L4: 75–95°C | M4: 70°C / 8h | N4: ⚠ | O4: ✗ | P4: ⚠ | Q4: ⚠ | R4: A | S4: Color and official 6-color line count confirmed (us.elegoo.com official product page — this catalog originally assumed a 12-color line; corrected to the real 6-color line this pass: Deep Black, White, Blue, ASA Green, Grey, Red); hex via 3dfilamentprofiles.com | T4: Cardboard spool — AMS Adapter Ring required for all AMS variants; enclosure recommended (ASA); AMS Lite ✗ (open-frame, no ASA support) | Hex: manufacturer-listed value (3dfilamentprofiles.com)
A5: ASA | B5: EL-ASA-BK | C5: Elegoo ASA | D5: Deep Black | F5: #101A25 | G5: 1.75mm | H5: ±0.03mm | I5: Cardboard | J5: Yes | K5: 240–260°C | L5: 75–95°C | M5: 70°C / 8h | N5: ⚠ | O5: ✗ | P5: ⚠ | Q5: ⚠ | R5: A | S5: Color and official 6-color line count confirmed (us.elegoo.com official product page — this catalog originally assumed a 12-color line; corrected to the real 6-color line this pass: Deep Black, White, Blue, ASA Green, Grey, Red); hex via 3dfilamentprofiles.com | T5: Manufacturer lists this as "Deep Black"; colorimeter-measured RGB (#101A25, a dark navy-black) differs meaningfully from the nominal listed #000000 | Cardboard spool — AMS Adapter Ring required for all AMS variants; enclosure recommended (ASA); AMS Lite ✗ (open-frame, no ASA support) | Hex: colorimeter-MEASURED value used (#101A25), which differs from the nominal/listed #000000 — measured value preferred as higher confidence (3dfilamentprofiles.com)
A6: ASA | B6: EL-ASA-GY | C6: Elegoo ASA | D6: Grey | F6: #999999 | G6: 1.75mm | H6: ±0.03mm | I6: Cardboard | J6: Yes | K6: 240–260°C | L6: 75–95°C | M6: 70°C / 8h | N6: ⚠ | O6: ✗ | P6: ⚠ | Q6: ⚠ | R6: C | S6: PLACEHOLDER — color and official 6-color line count confirmed (us.elegoo.com) but hex not found on 3dfilamentprofiles.com or any other source checked this pass | T6: Cardboard spool — AMS Adapter Ring required for all AMS variants; enclosure recommended (ASA); AMS Lite ✗ (open-frame, no ASA support) | Hex: unconfirmed placeholder
A7: ASA | B7: EL-ASA-RD | C7: Elegoo ASA | D7: Red | F7: #D61212 | G7: 1.75mm | H7: ±0.03mm | I7: Cardboard | J7: Yes | K7: 240–260°C | L7: 75–95°C | M7: 70°C / 8h | N7: ⚠ | O7: ✗ | P7: ⚠ | Q7: ⚠ | R7: A | S7: Color and official 6-color line count confirmed (us.elegoo.com official product page — this catalog originally assumed a 12-color line; corrected to the real 6-color line this pass: Deep Black, White, Blue, ASA Green, Grey, Red); hex via 3dfilamentprofiles.com | T7: Cardboard spool — AMS Adapter Ring required for all AMS variants; enclosure recommended (ASA); AMS Lite ✗ (open-frame, no ASA support) | Hex: manufacturer-listed value (3dfilamentprofiles.com)
A8: ASA | B8: EL-ASA-WH | C8: Elegoo ASA | D8: White | F8: #FFFFFF | G8: 1.75mm | H8: ±0.03mm | I8: Cardboard | J8: Yes | K8: 240–260°C | L8: 75–95°C | M8: 70°C / 8h | N8: ⚠ | O8: ✗ | P8: ⚠ | Q8: ⚠ | R8: A | S8: Color and official 6-color line count confirmed (us.elegoo.com official product page — this catalog originally assumed a 12-color line; corrected to the real 6-color line this pass: Deep Black, White, Blue, ASA Green, Grey, Red); hex via 3dfilamentprofiles.com | T8: Cardboard spool — AMS Adapter Ring required for all AMS variants; enclosure recommended (ASA); AMS Lite ✗ (open-frame, no ASA support) | Hex: manufacturer-listed value (3dfilamentprofiles.com)
A9: ASA-CF | B9: EL-ASACF-BK | C9: Elegoo ASA-CF | D9: Carbon Fiber Black | F9: #999999 | G9: 1.75mm | H9: ±0.03mm | I9: Cardboard | J9: Yes | K9: 240–260°C | L9: 85–105°C | M9: 85°C / 8h | N9: ⚠ | O9: ✗ | P9: ⚠ | Q9: ⚠ | R9: C | S9: PLACEHOLDER — color confirmed real (us.elegoo.com, 6-color line: Carbon Fiber Black/Grey/Red/Blue/Green/Sand) but hex not found this pass | T9: This color's own 3dfilamentprofiles.com page explicitly says "No RGB Provided" — a genuine absence, not unresearched | Cardboard spool — AMS Adapter Ring required for all AMS variants; enclosure recommended (ASA); AMS Lite ✗; abrasive — hardened nozzle required; heat resistance to 108°C per manufacturer | Hex: unconfirmed placeholder
A10: ASA-CF | B10: EL-ASACF-BL | C10: Elegoo ASA-CF | D10: Carbon Fiber Blue | F10: #999999 | G10: 1.75mm | H10: ±0.03mm | I10: Cardboard | J10: Yes | K10: 240–260°C | L10: 85–105°C | M10: 85°C / 8h | N10: ⚠ | O10: ✗ | P10: ⚠ | Q10: ⚠ | R10: C | S10: PLACEHOLDER — color confirmed real (us.elegoo.com, 6-color line: Carbon Fiber Black/Grey/Red/Blue/Green/Sand) but hex not found this pass | T10: This color's own 3dfilamentprofiles.com page explicitly says "— No data" — a genuine absence, not unresearched | Cardboard spool — AMS Adapter Ring required for all AMS variants; enclosure recommended (ASA); AMS Lite ✗; abrasive — hardened nozzle required; heat resistance to 108°C per manufacturer | Hex: unconfirmed placeholder
A11: ASA-CF | B11: EL-ASACF-GN | C11: Elegoo ASA-CF | D11: Carbon Fiber Green | F11: #007700 | G11: 1.75mm | H11: ±0.03mm | I11: Cardboard | J11: Yes | K11: 240–260°C | L11: 85–105°C | M11: 85°C / 8h | N11: ⚠ | O11: ✗ | P11: ⚠ | Q11: ⚠ | R11: A | S11: Color and official 6-color line count confirmed (us.elegoo.com official product page); hex via 3dfilamentprofiles.com | T11: Cardboard spool — AMS Adapter Ring required for all AMS variants; enclosure recommended (ASA); AMS Lite ✗; abrasive — hardened nozzle required; heat resistance to 108°C per manufacturer | Hex: manufacturer-listed value (3dfilamentprofiles.com)
A12: ASA-CF | B12: EL-ASACF-GY | C12: Elegoo ASA-CF | D12: Carbon Fiber Grey | F12: #999999 | G12: 1.75mm | H12: ±0.03mm | I12: Cardboard | J12: Yes | K12: 240–260°C | L12: 85–105°C | M12: 85°C / 8h | N12: ⚠ | O12: ✗ | P12: ⚠ | Q12: ⚠ | R12: C | S12: PLACEHOLDER — color confirmed real (us.elegoo.com, 6-color line: Carbon Fiber Black/Grey/Red/Blue/Green/Sand) but hex not found this pass | T12: This color's own 3dfilamentprofiles.com page explicitly says "No data" — a genuine absence, not unresearched | Cardboard spool — AMS Adapter Ring required for all AMS variants; enclosure recommended (ASA); AMS Lite ✗; abrasive — hardened nozzle required; heat resistance to 108°C per manufacturer | Hex: unconfirmed placeholder
A13: ASA-CF | B13: EL-ASACF-RD | C13: Elegoo ASA-CF | D13: Carbon Fiber Red | F13: #999999 | G13: 1.75mm | H13: ±0.03mm | I13: Cardboard | J13: Yes | K13: 240–260°C | L13: 85–105°C | M13: 85°C / 8h | N13: ⚠ | O13: ✗ | P13: ⚠ | Q13: ⚠ | R13: C | S13: PLACEHOLDER — color confirmed real (us.elegoo.com, 6-color line: Carbon Fiber Black/Grey/Red/Blue/Green/Sand) but hex not found this pass | T13: Cardboard spool — AMS Adapter Ring required for all AMS variants; enclosure recommended (ASA); AMS Lite ✗; abrasive — hardened nozzle required; heat resistance to 108°C per manufacturer | Hex: unconfirmed placeholder
A14: ASA-CF | B14: EL-ASACF-SND | C14: Elegoo ASA-CF | D14: Carbon Fiber Sand | F14: #999999 | G14: 1.75mm | H14: ±0.03mm | I14: Cardboard | J14: Yes | K14: 240–260°C | L14: 85–105°C | M14: 85°C / 8h | N14: ⚠ | O14: ✗ | P14: ⚠ | Q14: ⚠ | R14: C | S14: PLACEHOLDER — color confirmed real (us.elegoo.com, 6-color line: Carbon Fiber Black/Grey/Red/Blue/Green/Sand) but hex not found this pass | T14: Cardboard spool — AMS Adapter Ring required for all AMS variants; enclosure recommended (ASA); AMS Lite ✗; abrasive — hardened nozzle required; heat resistance to 108°C per manufacturer | Hex: unconfirmed placeholder
... A229: TPU 95A | B229: EL-TPU-WH | C229: Elegoo TPU 95A | D229: White | F229: #FFFFFF | G229: 1.75mm | H229: ±0.03mm | I229: Cardboard | J229: Yes | K229: 210–240°C | L229: 35–60°C | M229: 50°C / 8h | N229: ✗ | O229: ✗ | P229: ✗ | Q229: ✗ | R229: B | S229: Color and temps manufacturer-confirmed (us.elegoo.com product page, 7-color line; temps cross-checked via 3djake.com per-color listings); hex via MakerWorld community swatch set, exact name match | T229: Cardboard spool — AMS Adapter Ring required for all AMS variants; TPU is external-spool-only on Bambu AMS regardless of adapter ring | Hex: community-sourced (MakerWorld), not manufacturer-confirmed

Sheet Material Guide
A1: Elegoo — Material Guide
A2: Material | B2: Print Temp Range | C2: Bed Temp Range | D2: Enclosure Required | E2: AMS Compatible | F2: Drying Required | G2: Drying Temp / Time | H2: Notes
A3: PLA | B3: 190–220°C | C3: 45–60°C | D3: No | E3: ⚠ | F3: Recommended | G3: 45°C / 4h | H3: Cardboard spool, ~199-200mm OD — AMS Adapter Ring required for all AMS variants. Hex codes are community-sourced (MakerWorld), not manufacturer-published.
A4: PLA Basic | B4: 190–230°C | C4: 35–65°C | D4: No | E4: ⚠ | F4: Recommended | G4: 55°C / 6h | H4: Cardboard spool — AMS Adapter Ring required. Distinct product line from plain "PLA" with different colors and (where checked) different hex for same-named colors — not cross-referenced. Color count varies by region: 19 (US) up to 24-25 (AU/other storefronts) — not reconciled this pass.
A5: PLA Plus | B5: 190–220°C | C5: 45–60°C | D5: No | E5: ⚠ | F5: Recommended | G5: 45°C / 4h | H5: Cardboard spool — AMS Adapter Ring required. Same 17 color names as the plain PLA line; hex from the same community swatch set, which explicitly covers PLA+.
A6: TPU 95A | B6: 210–240°C | C6: 35–60°C | D6: No | E6: No | F6: Yes | G6: 50°C / 8h | H6: Cardboard spool. External-spool-only on Bambu AMS regardless of adapter ring, same as every other brand's TPU in this catalog. 7-color line, only 4/7 hex confirmed this pass (Black/White/Grey/Red) — Blue/Green/Translucent use different color names than the source swatch's PLA-line entries, not assumed identical.
A7: ASA | B7: 240–260°C | C7: 75–95°C | D7: Yes | E7: ⚠ | F7: Yes | G7: 70°C / 8h | H7: Cardboard spool — AMS Adapter Ring required; AMS Lite incompatible (open-frame). Real 6-color line (Deep Black, White, Blue, ASA Green, Grey, Red) — this catalog originally assumed 12 colors in error, corrected 2026-09-23. Deep Black uses a colorimeter-measured hex, not the flat nominal value most retailers list.
A8: PETG (Rapid) | B8: 240–270°C | C8: 65–75°C | D8: No | E8: ⚠ | F8: Yes | G8: 65°C / 8h | H8: Cardboard spool — AMS Adapter Ring required. 12-color line, 8/12 hex confirmed. Yellow deliberately left unresolved — two different manufacturer-sourced listings gave conflicting hex for this exact color, not resolved without a physical-spool tiebreaker.
A9: PLA Pro | B9: 190–230°C | C9: 35–65°C | D9: No | E9: ⚠ | F9: Recommended | G9: 55°C / 6h | H9: Cardboard spool — AMS Adapter Ring required. 14-color line, only 1/14 hex confirmed this pass (Burgundy Red) — this line proved unusually hard to source per-color data for; worth a dedicated follow-up pass.
A10: PLA (RFID) emoji Brand Edition | B10: 190–220°C | C10: 45–60°C | D10: No | E10: ⚠ | F10: Recommended | G10: 45°C / 4h | H10: Cardboard spool — AMS Adapter Ring required. Brand-new pre-order product as of 2026-09-27, RFID-tagged for ELEGOO CANVAS. Same 17 color names as PLA Plus. Zero hex confirmed — too new to be indexed by any third-party source checked; re-check once this line has fully shipped.
A11: PLA Marble | B11: 190–220°C | C11: 35–65°C | D11: No | E11: ⚠ | F11: Recommended | G11: 55°C / 8h | H11: Cardboard spool — AMS Adapter Ring required. 3-color line, all 3 hex resolved, but two of the three (Marble, Marble Cement Grey) have conflicting values across sources within 3dfilamentprofiles.com itself — flagged per-entry, not reconciled. Stone-like surface texture over a solid pigment, not a multi-color blend.
A12: PLA Sparkle | B12: 190–220°C | C12: 35–65°C | D12: No | E12: ⚠ | F12: Recommended | G12: 55°C / 6h | H12: Cardboard spool — AMS Adapter Ring required. 7-color line, 6/7 hex resolved; Sparkle Green left unresolved due to conflicting source values (#004000 vs #38571A). Glitter-particle additive, slightly abrasive — monitor nozzle wear.
A13: ASA-CF | B13: 240–260°C | C13: 85–105°C | D13: Yes | E13: ⚠ | F13: Yes | G13: 85°C / 8h | H13: Cardboard spool — AMS Adapter Ring required; AMS Lite incompatible; abrasive, hardened nozzle required. 6-color line, only 1/6 hex resolved (Green) — Black/Grey/Blue explicitly show no RGB data on their own source pages (genuine absence, not unresearched); Red/Sand never surfaced.
... A25: PETG-CF | B25: 240–270°C | C25: 65–75°C | D25: No | E25: ⚠ | F25: Yes | G25: 65°C / 8h | H25: Cardboard spool — AMS Adapter Ring required; AMS Lite incompatible; abrasive, hardened nozzle required. Added 2026-10-08. 5-color line (Carbon Fiber Blue/Green/Grey/Purple/Red) confirmed via retailer listings (elegoo.com's own product page couldn't be fetched this pass). 5/5 hex resolved via 3dfilamentprofiles.com, which also separately lists Black/Carbon Fiber Black entries not matched to a current retailer listing for this line — not added as a 6th color.

Sheet Config
A1: ⚙ Configuration
A2: Setting | B2: Value | C2: Notes
A3: Brand | B3: Elegoo
A4: File Version | B4: v3
A5: Generated | B5: 2026-10-08 | C5: Date this file was last generated by generate_all.py
A6: SKU Note | B6: Reference codes — verify at manufacturer site | C6: SKU column: confirmed mfr codes noted above; others are internal reference codes
A7: Hex Note | B7: Per-row confirmation status is tracked in each Catalog row's Notes column (manufacturer TDS-confirmed, official product-page confirmed, or unconfirmed placeholder). #999999 in the Hex Code column always means unconfirmed placeholder, not a real color. | C7: Approximate hex = visually representative; not manufacturer-confirmed
A8: Inventory Note | B8: This workbook covers catalog reference data only. On-hand spool inventory is tracked separately in Filament_Inventory.xlsx. | C8: Split from per-brand Inventory Tracker sheets, 2026-07-23
